<?xml version="1.0" ?>
<!-- =================================================================================== -->
<!-- |    This document was autogenerated by xacro from snacbot.xacro                  | -->
<!-- |    EDITING THIS FILE BY HAND IS NOT RECOMMENDED                                 | -->
<!-- =================================================================================== -->
<robot name="snacbot">
  <material name="silver">
    <color rgba="0.700 0.700 0.700 1.000"/>
  </material>
  <transmission name="waist_joint_tran">
    <type>transmission_interface/SimpleTransmission</type>
    <joint name="waist_joint">
      <hardwareInterface>hardware_interface/EffortJointInterface</hardwareInterface>
    </joint>
    <actuator name="waist_joint_actr">
      <hardwareInterface>hardware_interface/EffortJointInterface</hardwareInterface>
      <mechanicalReduction>1</mechanicalReduction>
    </actuator>
  </transmission>
  <transmission name="shoulder_joint_tran">
    <type>transmission_interface/SimpleTransmission</type>
    <joint name="shoulder_joint">
      <hardwareInterface>hardware_interface/EffortJointInterface</hardwareInterface>
    </joint>
    <actuator name="shoulder_joint_actr">
      <hardwareInterface>hardware_interface/EffortJointInterface</hardwareInterface>
      <mechanicalReduction>1</mechanicalReduction>
    </actuator>
  </transmission>
  <transmission name="elbow_joint_tran">
    <type>transmission_interface/SimpleTransmission</type>
    <joint name="elbow_joint">
      <hardwareInterface>hardware_interface/EffortJointInterface</hardwareInterface>
    </joint>
    <actuator name="elbow_joint_actr">
      <hardwareInterface>hardware_interface/EffortJointInterface</hardwareInterface>
      <mechanicalReduction>1</mechanicalReduction>
    </actuator>
  </transmission>
  <transmission name="wrist_joint_tran">
    <type>transmission_interface/SimpleTransmission</type>
    <joint name="wrist_joint">
      <hardwareInterface>hardware_interface/EffortJointInterface</hardwareInterface>
    </joint>
    <actuator name="wrist_joint_actr">
      <hardwareInterface>hardware_interface/EffortJointInterface</hardwareInterface>
      <mechanicalReduction>1</mechanicalReduction>
    </actuator>
  </transmission>
  <transmission name="palm_joint_tran">
    <type>transmission_interface/SimpleTransmission</type>
    <joint name="palm_joint">
      <hardwareInterface>hardware_interface/EffortJointInterface</hardwareInterface>
    </joint>
    <actuator name="palm_joint_actr">
      <hardwareInterface>hardware_interface/EffortJointInterface</hardwareInterface>
      <mechanicalReduction>1</mechanicalReduction>
    </actuator>
  </transmission>
  <transmission name="gripper_joint_tran">
    <type>transmission_interface/SimpleTransmission</type>
    <joint name="gripper_joint">
      <hardwareInterface>hardware_interface/EffortJointInterface</hardwareInterface>
    </joint>
    <actuator name="gripper_joint_actr">
      <hardwareInterface>hardware_interface/EffortJointInterface</hardwareInterface>
      <mechanicalReduction>1</mechanicalReduction>
    </actuator>
  </transmission>
  <transmission name="finger1_joint_tran">
    <type>transmission_interface/SimpleTransmission</type>
    <joint name="finger1_joint">
      <hardwareInterface>hardware_interface/EffortJointInterface</hardwareInterface>
    </joint>
    <actuator name="finger1_joint_actr">
      <hardwareInterface>hardware_interface/EffortJointInterface</hardwareInterface>
      <mechanicalReduction>1</mechanicalReduction>
    </actuator>
  </transmission>
  <transmission name="finger2_joint_tran">
    <type>transmission_interface/SimpleTransmission</type>
    <joint name="finger2_joint">
      <hardwareInterface>hardware_interface/EffortJointInterface</hardwareInterface>
    </joint>
    <actuator name="finger2_joint_actr">
      <hardwareInterface>hardware_interface/EffortJointInterface</hardwareInterface>
      <mechanicalReduction>1</mechanicalReduction>
    </actuator>
  </transmission>
  <gazebo>
    <plugin filename="libgazebo_ros_control.so" name="control"/>
  </gazebo>
  <gazebo reference="base_link">
    <material>Gazebo/Silver</material>
    <mu1>0.2</mu1>
    <mu2>0.2</mu2>
    <selfCollide>true</selfCollide>
    <gravity>true</gravity>
  </gazebo>
  <gazebo reference="shoulder_link">
    <material>Gazebo/Silver</material>
    <mu1>0.2</mu1>
    <mu2>0.2</mu2>
    <selfCollide>true</selfCollide>
  </gazebo>
  <gazebo reference="arm_link">
    <material>Gazebo/Silver</material>
    <mu1>0.2</mu1>
    <mu2>0.2</mu2>
    <selfCollide>true</selfCollide>
  </gazebo>
  <gazebo reference="forearm_link">
    <material>Gazebo/Silver</material>
    <mu1>0.2</mu1>
    <mu2>0.2</mu2>
    <selfCollide>true</selfCollide>
  </gazebo>
  <gazebo reference="hand_link">
    <material>Gazebo/Silver</material>
    <mu1>0.2</mu1>
    <mu2>0.2</mu2>
    <selfCollide>true</selfCollide>
  </gazebo>
  <gazebo reference="palm_link">
    <material>Gazebo/Silver</material>
    <mu1>0.2</mu1>
    <mu2>0.2</mu2>
    <selfCollide>true</selfCollide>
  </gazebo>
  <gazebo reference="gripper_driving_link">
    <material>Gazebo/Silver</material>
    <mu1>0.2</mu1>
    <mu2>0.2</mu2>
    <selfCollide>true</selfCollide>
  </gazebo>
  <gazebo reference="finger1_link">
    <material>Gazebo/Silver</material>
    <mu1>0.2</mu1>
    <mu2>0.2</mu2>
    <selfCollide>true</selfCollide>
  </gazebo>
  <gazebo reference="finger2_link">
    <material>Gazebo/Silver</material>
    <mu1>0.2</mu1>
    <mu2>0.2</mu2>
    <selfCollide>true</selfCollide>
  </gazebo>
  <material name="aluminum">
    <color rgba="0.5 0.5 0.5 1"/>
  </material>
  <material name="plastic">
    <color rgba="0.1 0.1 0.1 1"/>
  </material>
  <link name="world"/>
  <link name="base_link">
    <inertial>
      <origin rpy="0 0 0" xyz="0.0023657954446381375 -6.614240985321828e-05 0.03556496392903804"/>
      <mass value="1.5030270945970066"/>
      <inertia ixx="0.002425" ixy="1e-06" ixz="-4.8e-05" iyy="0.002489" iyz="-1e-05" izz="0.003322"/>
    </inertial>
    <visual>
      <origin rpy="0 0 0" xyz="0 0 0"/>
      <geometry>
        <mesh filename="package://snacbot_description/meshes/base_link.stl" scale="0.001 0.001 0.001"/>
      </geometry>
      <material name="silver"/>
    </visual>
    <collision>
      <origin rpy="0 0 0" xyz="0 0 0"/>
      <geometry>
        <mesh filename="package://snacbot_description/meshes/base_link.stl" scale="0.001 0.001 0.001"/>
      </geometry>
    </collision>
  </link>
  <link name="shoulder_link">
    <inertial>
      <origin rpy="0 0 0" xyz="-3.5710799003101265e-16 -9.70255671027657e-16 0.021007556766470648"/>
      <mass value="0.9933845675779478"/>
      <inertia ixx="0.001482" ixy="0.0" ixz="-0.0" iyy="0.000491" iyz="-0.0" izz="0.001397"/>
    </inertial>
    <visual>
      <origin rpy="0 0 0" xyz="0.0 -0.0 -0.073675"/>
      <geometry>
        <mesh filename="package://snacbot_description/meshes/shoulder_link_1.stl" scale="0.001 0.001 0.001"/>
      </geometry>
      <material name="silver"/>
    </visual>
    <collision>
      <origin rpy="0 0 0" xyz="0.0 -0.0 -0.073675"/>
      <geometry>
        <mesh filename="package://snacbot_description/meshes/shoulder_link_1.stl" scale="0.001 0.001 0.001"/>
      </geometry>
    </collision>
  </link>
  <link name="arm_link">
    <inertial>
      <origin rpy="0 0 0" xyz="0.006643024417772186 0.009009733316364827 0.15284041528327338"/>
      <mass value="0.7694455801037552"/>
      <inertia ixx="0.003903" ixy="-1e-06" ixz="-0.000266" iyy="0.003957" iyz="-0.0" izz="0.00022"/>
    </inertial>
    <visual>
      <origin rpy="0 0 0" xyz="-0.0 0.009 -0.113675"/>
      <geometry>
        <mesh filename="package://snacbot_description/meshes/arm_link_1.stl" scale="0.001 0.001 0.001"/>
      </geometry>
      <material name="silver"/>
    </visual>
    <collision>
      <origin rpy="0 0 0" xyz="-0.0 0.009 -0.113675"/>
      <geometry>
        <mesh filename="package://snacbot_description/meshes/arm_link_1.stl" scale="0.001 0.001 0.001"/>
      </geometry>
    </collision>
  </link>
  <link name="arm_shadow_link">
    <origin rpy="0 0 0" xyz="-0.0 0.009 -0.113675"/>
  </link>
  <link name="forearm_link">
    <inertial>
      <origin rpy="0 0 0" xyz="0.12530362498320322 0.02051079804018362 0.007019037615682622"/>
      <mass value="0.6930776096733422"/>
      <inertia ixx="0.000161" ixy="-2e-06" ixz="-0.000204" iyy="0.002362" iyz="-0.0" izz="0.00239"/>
    </inertial>
    <visual>
      <origin rpy="0 0 0" xyz="-0.027 0.020075 -0.317875"/>
      <geometry>
        <mesh filename="package://snacbot_description/meshes/forearm_link_1.stl" scale="0.001 0.001 0.001"/>
      </geometry>
      <material name="silver"/>
    </visual>
    <collision>
      <origin rpy="0 0 0" xyz="-0.027 0.020075 -0.317875"/>
      <geometry>
        <mesh filename="package://snacbot_description/meshes/forearm_link_1.stl" scale="0.001 0.001 0.001"/>
      </geometry>
    </collision>
  </link>
  <link name="hand_link">
    <inertial>
      <origin rpy="0 0 0" xyz="0.04152167158553119 0.02011849033469139 -0.010784557589962995"/>
      <mass value="0.4498637120159831"/>
      <inertia ixx="0.000148" ixy="1e-06" ixz="2.7e-05" iyy="0.000224" iyz="-0.0" izz="0.000198"/>
    </inertial>
    <visual>
      <origin rpy="0 0 0" xyz="-0.2078 0.01965 -0.330375"/>
      <geometry>
        <mesh filename="package://snacbot_description/meshes/hand_link_1.stl" scale="0.001 0.001 0.001"/>
      </geometry>
      <material name="silver"/>
    </visual>
    <collision>
      <origin rpy="0 0 0" xyz="-0.2078 0.01965 -0.330375"/>
      <geometry>
        <mesh filename="package://snacbot_description/meshes/hand_link_1.stl" scale="0.001 0.001 0.001"/>
      </geometry>
    </collision>
  </link>
  <link name="palm_link">
    <inertial>
      <origin rpy="0 0 0" xyz="0.03514107719512616 0.00028468032824946964 0.0011739025280478876"/>
      <mass value="0.5485700850055245"/>
      <inertia ixx="0.00015" ixy="-0.0" ixz="-1.2e-05" iyy="0.000191" iyz="-0.0" izz="0.0002"/>
    </inertial>
    <visual>
      <origin rpy="0 0 0" xyz="-0.27311 -0.00045 -0.330325"/>
      <geometry>
        <mesh filename="package://snacbot_description/meshes/palm_link_1.stl" scale="0.001 0.001 0.001"/>
      </geometry>
      <material name="silver"/>
    </visual>
    <collision>
      <origin rpy="0 0 0" xyz="-0.27311 -0.00045 -0.330325"/>
      <geometry>
        <mesh filename="package://snacbot_description/meshes/palm_link_1.stl" scale="0.001 0.001 0.001"/>
      </geometry>
    </collision>
  </link>
  <!-- camera body, with origin at bottom screw mount -->
  <joint name="camera_joint" type="fixed">
    <origin rpy="0 0 0" xyz="0.04 0 0.035"/>
    <parent link="palm_link"/>
    <child link="camera_bottom_screw_frame"/>
  </joint>
  <link name="camera_bottom_screw_frame"/>
  <joint name="camera_link_joint" type="fixed">
    <origin rpy="0 0 0" xyz="0.010600000000000002 0.0175 0.0125"/>
    <parent link="camera_bottom_screw_frame"/>
    <child link="camera_link"/>
  </joint>
  <link name="camera_link">
    <visual>
      <!-- the mesh origin is at front plate in between the two infrared camera axes -->
      <origin rpy="1.5707963267948966 0 1.5707963267948966" xyz="0.0043 -0.0175 0"/>
      <geometry>
        <mesh filename="package://realsense2_description/meshes/d435.dae"/>
      </geometry>
    </visual>
    <collision>
      <origin rpy="0 0 0" xyz="0 -0.0175 0"/>
      <geometry>
        <box size="0.02505 0.09 0.025"/>
      </geometry>
    </collision>
    <inertial>
      <!-- The following are not reliable values, and should not be used for modeling -->
      <mass value="0.072"/>
      <origin xyz="0 0 0"/>
      <inertia ixx="0.003881243" ixy="0.0" ixz="0.0" iyy="0.000498940" iyz="0.0" izz="0.003879257"/>
    </inertial>
  </link>
  <link name="gripper_driving_link">
    <inertial>
      <origin rpy="0 0 0" xyz="-4.267483755260315e-09 7.6050195998832865e-06 0.002017482694919248"/>
      <mass value="0.009329279902749366"/>
      <inertia ixx="0.0" ixy="-0.0" ixz="-0.0" iyy="0.0" iyz="-0.0" izz="1e-06"/>
    </inertial>
    <visual>
      <origin rpy="0 0 0" xyz="-0.32015 -0.000756 -0.309525"/>
      <geometry>
        <mesh filename="package://snacbot_description/meshes/gripper_driving_link_1.stl" scale="0.001 0.001 0.001"/>
      </geometry>
      <material name="silver"/>
    </visual>
    <collision>
      <origin rpy="0 0 0" xyz="-0.32015 -0.000756 -0.309525"/>
      <geometry>
        <mesh filename="package://snacbot_description/meshes/gripper_driving_link_1.stl" scale="0.001 0.001 0.001"/>
      </geometry>
    </collision>
  </link>
  <link name="finger1_link">
    <inertial>
      <origin rpy="0 0 0" xyz="0.04341596099355033 0.00717258179909807 0.009580165880901437"/>
      <mass value="0.14441482713674805"/>
      <inertia ixx="2e-05" ixy="-2.9e-05" ixz="-2e-06" iyy="0.000111" iyz="-1e-06" izz="0.000116"/>
    </inertial>
    <visual>
      <origin rpy="0 0 0" xyz="-0.30115 0.023244 -0.320325"/>
      <geometry>
        <mesh filename="package://snacbot_description/meshes/finger1_link_1.stl" scale="0.001 0.001 0.001"/>
      </geometry>
      <material name="silver"/>
    </visual>
    <collision>
      <origin rpy="0 0 0" xyz="-0.30115 0.023244 -0.320325"/>
      <geometry>
        <mesh filename="package://snacbot_description/meshes/finger1_link_1.stl" scale="0.001 0.001 0.001"/>
      </geometry>
    </collision>
  </link>
  <link name="finger2_link">
    <inertial>
      <origin rpy="0 0 0" xyz="0.043415960993547276 -0.007172063661821274 0.009580165880900049"/>
      <mass value="0.14441482713674192"/>
      <inertia ixx="2e-05" ixy="2.9e-05" ixz="-2e-06" iyy="0.000111" iyz="1e-06" izz="0.000116"/>
    </inertial>
    <visual>
      <origin rpy="0 0 0" xyz="-0.30115 -0.024756 -0.320325"/>
      <geometry>
        <mesh filename="package://snacbot_description/meshes/finger2_link_1.stl" scale="0.001 0.001 0.001"/>
      </geometry>
      <material name="silver"/>
    </visual>
    <collision>
      <origin rpy="0 0 0" xyz="-0.30115 -0.024756 -0.320325"/>
      <geometry>
        <mesh filename="package://snacbot_description/meshes/finger2_link_1.stl" scale="0.001 0.001 0.001"/>
      </geometry>
    </collision>
  </link>
  <link name="ee_link">
    <origin rpy="0 0 0" xyz="0 0 0"/>
  </link>
  <joint name="base_joint" type="fixed">
    <parent link="world"/>
    <child link="base_link"/>
  </joint>
  <joint name="waist_joint" type="revolute">
    <origin rpy="0 0 0" xyz="0.0 0.0 0.073675"/>
    <parent link="base_link"/>
    <child link="shoulder_link"/>
    <axis xyz="0.0 0.0 1.0"/>
    <limit effort="300" lower="-3.14" upper="3.14" velocity="4.01"/>
  </joint>
  <joint name="shoulder_joint" type="revolute">
    <origin rpy="0 0 0" xyz="0.0 -0.009 0.04"/>
    <parent link="shoulder_link"/>
    <child link="arm_link"/>
    <axis xyz="0.0 1.0 0.0"/>
    <limit effort="300" lower="-1.85" upper="1.85" velocity="4.01"/>
  </joint>
  <joint name="shoulder_shadow_joint" type="continuous">
    <origin rpy="0 0 0" xyz="0.0 -0.009 0.04"/>
    <parent link="shoulder_link"/>
    <child link="arm_shadow_link"/>
    <axis xyz="0.0 1.0 0.0"/>
    <mimic joint="shoulder_joint" multiplier="-1" offset="0"/>
  </joint>
  <joint name="elbow_joint" type="revolute">
    <origin rpy="0 0 0" xyz="0.027 -0.011075 0.2042"/>
    <parent link="arm_link"/>
    <child link="forearm_link"/>
    <axis xyz="0.0 -1.0 0.0"/>
    <limit effort="300" lower="-1.5" upper="1.6" velocity="4.01"/>
  </joint>
  <joint name="wrist_joint" type="revolute">
    <origin rpy="0 0 0" xyz="0.1808 0.000425 0.0125"/>
    <parent link="forearm_link"/>
    <child link="hand_link"/>
    <axis xyz="-0.0 -1.0 0.0"/>
    <limit effort="300" lower="-1.6" upper="1.85" velocity="4.01"/>
  </joint>
  <joint name="palm_joint" type="revolute">
    <origin rpy="0 0 0" xyz="0.06531 0.0201 -5e-05"/>
    <parent link="hand_link"/>
    <child link="palm_link"/>
    <axis xyz="1.0 0.0 0.0"/>
    <limit effort="300" lower="-1.6" upper="1.6" velocity="4.01"/>
  </joint>
  <joint name="gripper_joint" type="revolute">
    <origin rpy="0 0 0" xyz="0.04704 0.000306 -0.0208"/>
    <parent link="palm_link"/>
    <child link="gripper_driving_link"/>
    <axis xyz="-0.0 -0.0 1.0"/>
    <limit effort="300" lower="0.26" upper="2.6" velocity="4.01"/>
  </joint>
  <joint name="finger1_joint" type="continuous">
    <origin rpy="0 0 0" xyz="0.02804 -0.023694 -0.01"/>
    <parent link="palm_link"/>
    <child link="finger1_link"/>
    <axis xyz="0.0 0.0 -1.0"/>
    <mimic joint="gripper_joint" multiplier="0.33" offset="0"/>
  </joint>
  <joint name="finger2_joint" type="continuous">
    <origin rpy="0 0 0" xyz="0.02804 0.024306 -0.01"/>
    <parent link="palm_link"/>
    <child link="finger2_link"/>
    <axis xyz="0.0 0.0 -1.0"/>
    <mimic joint="gripper_joint" multiplier="-0.33" offset="0"/>
  </joint>
  <joint name="ee_joint" type="fixed">
    <origin rpy="0 0 0" xyz="0.126 0.0 0.0"/>
    <parent link="palm_link"/>
    <child link="ee_link"/>
  </joint>
</robot>

